<?xml version="1.0"?>
<robot name="simple_gripper" xmlns:xacro="http://ros.org/wiki/xacro">

  <xacro:macro name="finger" params="suffix">
   <link name="finger${suffix}">
    <visual>
      <geometry>
        <box size="0.02 0.05 0.3"/>
      </geometry>
      <origin rpy="0 0 0" xyz="0 0 0.06"/>
      <material name="fing">
        <color rgba="1 0.5 0 1" />
      </material>
    </visual>
    <collision>
      <geometry>
        <box size="0.02 0.05 0.3"/>
      </geometry>
      <origin rpy="0 0 0" xyz="0 0 0.06"/>
    </collision>
    <inertial>
      <mass value="0.1"/>
      <inertia ixx="0.001" ixy="0.0" ixz="0.0" iyy="0.001" iyz="0.0" izz="0.001"/>
    </inertial>
   </link>
   <gazebo reference="finger${suffix}">
     <material>Gazebo/Orange</material>
   </gazebo>

  <!-- Pads -->
   <link name="pad${suffix}">
    <visual>
      <geometry>
        <box size="0.02 0.04 0.26"/>
      </geometry>
      <origin rpy="0 0 0" xyz="0 0 0.02"/>
      <material name="pad">
        <color rgba="0.2 0.2 0.2 1" />
      </material>
    </visual>
    <collision>
      <geometry>
        <box size="0.02 0.04 0.08"/>
      </geometry>
      <origin rpy="0 0 0" xyz="0 0 0.02"/>
    </collision>
    <inertial>
      <mass value="0.01"/>
      <inertia ixx="0.001" ixy="0.0" ixz="0.0" iyy="0.001" iyz="0.0" izz="0.001"/>
    </inertial>
   </link>
   <gazebo reference="pad${suffix}">
     <material>Gazebo/Grey</material>
   </gazebo>

   <joint name="finger${suffix}_to_pad${suffix}" type="fixed">
    <parent link="finger${suffix}"/>
    <child link="pad${suffix}"/>
    <origin xyz="0.013 0 0.06" rpy="0 0 0"/> <!-- Changed from rpy = '0 0.1 0' to prevent drooping of pad at the end of the gripper-->
   </joint>




   <!-- make the pad squishy -->
   <gazebo reference="pad${suffix}">
    <mu1 value="10.0" />
    <mu2 value="10.0" />
    <kp  value="10000000" />	
   </gazebo>

  </xacro:macro>

  <xacro:macro name="simple_gripper" params="parent_link *origin">

   <link name="palm">
      <visual>
        <geometry>
          <box size="0.2 0.1 0.04" />
        </geometry>
        <origin rpy="0 0 0" xyz="0 0 0.02"/>
        <material name="palm">
          <color rgba="1 0.5 0 1" />
        </material>
      </visual>
      <collision>
        <geometry>
          <box size="0.2 0.1 0.04" />
        </geometry>
        <origin rpy="0 0 0" xyz="0 0 0.02"/>
      </collision>
      <inertial>
        <mass value="0.1"/>
        <inertia ixx="0.001" ixy="0.0" ixz="0.0" iyy="0.001" iyz="0.0" izz="0.001"/>
      </inertial>
    </link>
    <gazebo reference="palm">
      <material>Gazebo/Orange</material>
    </gazebo>

       <!-- Contact sensor -->
    <link name="contact_sensor_link">
        <collision name="contact_sensor_collision">
            <origin xyz="0 0 0" rpy="0 0 0"/>
            <geometry>
                <box size = "0.02 0.04 0.26"/>
            </geometry>
        </collision>

        <visual>
            <origin xyz="0 0 0" rpy="0 0 0"/>
            <geometry>
                <box size = "0.02 0.04 0.26"/>
            </geometry>
        </visual>

    </link>
    <gazebo reference="contact_sensor_link">
        <sensor name='my_contact' type='contact'>
          <always_on>1</always_on>
          <update_rate>0.5</update_rate>
          <contact>
              <collision>contact_sensor_collision_collision</collision>
              <topic>/contact_sensor</topic>
          </contact>
      </sensor>
      <material>Gazebo/Red</material>
    </gazebo>

    <!-- make two fingers -->
    <xacro:finger suffix="1" />
    <xacro:finger suffix="2" />


    <!-- Join sensor to pad-->
    <joint name="sensor1_to_pad1" type="fixed">
      <parent link="pad1" />
      <child link = "contact_sensor_link" />
      <origin xyz="0.01 0 0.005" rpy="0 0 0"/>
    </joint>



    <!-- fingers can slide -->

    <joint name="palm_to_finger1" type="prismatic">
      <parent link="palm"/>
      <child link="finger1"/>
      <limit effort="100.0" lower="-0.03" upper="0.045" velocity="0.05"/>
      <origin xyz="0.06 0 0.1" rpy="0 0 3.14159265"/> 	<!-- Changed the z coord from 0.04 to 0.1 -->
    </joint>

    <joint name="palm_to_finger2" type="prismatic">
      <parent link="palm"/>
      <child link="finger2"/>
      <limit effort="100.0" lower="-0.03" upper="0.045" velocity="0.05"/>
      <origin xyz="-0.06 0 0.1"/>	<!-- Changed the z coord from 0.04 to 0.1 -->
    </joint>

    <transmission name="finger1_trans">
      <type>transmission_interface/SimpleTransmission</type>
      <actuator name="finger1_motor">
        <mechanicalReduction>1</mechanicalReduction>
      </actuator>
      <joint name="palm_to_finger1">
        <hardwareInterface>hardware_interface/EffortJointInterface</hardwareInterface>
      </joint>
    </transmission>

    <transmission name="finger2_trans">
      <type>transmission_interface/SimpleTransmission</type>
      <actuator name="finger2_motor">
        <mechanicalReduction>1</mechanicalReduction>
      </actuator>
      <joint name="palm_to_finger2">
        <hardwareInterface>hardware_interface/EffortJointInterface</hardwareInterface>
      </joint>
    </transmission>

    <!-- fix the gripper to the parent -->
    <joint name="gripper_to_arm" type="fixed">
      <parent link="${parent_link}" />
      <child link = "palm" />
      <xacro:insert_block name="origin" />
    </joint>

  </xacro:macro>

</robot>
